<?xml version="1.0"?>
<sdf version="1.6">
  <model name="robot3">

    <link name="base_link">
      <inertial>
        <mass>1.5</mass>
        <inertia><ixx>0.02</ixx><ixy>0</ixy><ixz>0</ixz>
                 <iyy>0.02</iyy><iyz>0</iyz><izz>0.03</izz></inertia>
      </inertial>
      <collision name="col">
        <geometry><cylinder><radius>0.15</radius><length>0.10</length></cylinder></geometry>
      </collision>
      <visual name="body">
        <geometry><cylinder><radius>0.15</radius><length>0.10</length></cylinder></geometry>
        <material>
          <ambient>0.3 1.0 0.4 1</ambient>
          <diffuse>0.3 1.0 0.4 1</diffuse>
        </material>
      </visual>
      <visual name="nose">
        <pose>0.16 0 0 0 0 0</pose>
        <geometry><box><size>0.07 0.05 0.05</size></box></geometry>
        <material><ambient>1 1 1 1</ambient><diffuse>1 1 1 1</diffuse></material>
      </visual>
    </link>

    <link name="left_wheel">
      <pose>0 0.17 -0.03 -1.5708 0 0</pose>
      <inertial><mass>0.1</mass>
        <inertia><ixx>0.0001</ixx><iyy>0.0001</iyy><izz>0.0001</izz></inertia>
      </inertial>
      <collision name="col">
        <geometry><cylinder><radius>0.05</radius><length>0.04</length></cylinder></geometry>
      </collision>
      <visual name="vis">
        <geometry><cylinder><radius>0.05</radius><length>0.04</length></cylinder></geometry>
        <material><ambient>0.15 0.15 0.15 1</ambient><diffuse>0.15 0.15 0.15 1</diffuse></material>
      </visual>
    </link>

    <link name="right_wheel">
      <pose>0 -0.17 -0.03 -1.5708 0 0</pose>
      <inertial><mass>0.1</mass>
        <inertia><ixx>0.0001</ixx><iyy>0.0001</iyy><izz>0.0001</izz></inertia>
      </inertial>
      <collision name="col">
        <geometry><cylinder><radius>0.05</radius><length>0.04</length></cylinder></geometry>
      </collision>
      <visual name="vis">
        <geometry><cylinder><radius>0.05</radius><length>0.04</length></cylinder></geometry>
        <material><ambient>0.15 0.15 0.15 1</ambient><diffuse>0.15 0.15 0.15 1</diffuse></material>
      </visual>
    </link>

    <joint name="left_wheel_joint" type="revolute">
      <parent>base_link</parent><child>left_wheel</child>
      <axis><xyz>0 0 1</xyz>
        <limit><lower>-1e16</lower><upper>1e16</upper></limit></axis>
    </joint>

    <joint name="right_wheel_joint" type="revolute">
      <parent>base_link</parent><child>right_wheel</child>
      <axis><xyz>0 0 1</xyz>
        <limit><lower>-1e16</lower><upper>1e16</upper></limit></axis>
    </joint>

    <!-- Explicit full topic paths so each robot gets its own scoped topic -->
    <plugin filename="gz-sim-diff-drive-system"
            name="gz::sim::systems::DiffDrive">
      <left_joint>left_wheel_joint</left_joint>
      <right_joint>right_wheel_joint</right_joint>
      <wheel_separation>0.34</wheel_separation>
      <wheel_radius>0.05</wheel_radius>
      <topic>/model/robot3/cmd_vel</topic>
    </plugin>

    <!-- Ground-truth odometry (model pose, not wheel encoders). -->
    <plugin filename="gz-sim-odometry-publisher-system"
            name="gz::sim::systems::OdometryPublisher">
      <odom_frame>odom</odom_frame>
      <robot_base_frame>robot3/base_link</robot_base_frame>
      <odom_publish_frequency>20</odom_publish_frequency>
      <odom_topic>/model/robot3/odometry</odom_topic>
      <dimensions>2</dimensions>
    </plugin>

  </model>
</sdf>
